<?xml version="1.0"?>
<robot name="line_follower">
 	 <material name="red">
        <color rgba="1 0 0 1"/>
    </material>

    <material name="blue">
        <color rgba="0 0 1 1"/>
    </material>
  
    <material name="green">
        <color rgba="0 1 0 1"/>
    </material>  

    <material name="black">
        <color rgba="0 0 0 1"/>
    </material>

    <material name="gray">
        <color rgba="1 0 0 1"/>
    </material>
  
	<link name="chassis">
    	<visual>
          <geometry>
				    <mesh filename="./motoko_uprising.obj" scale="0.001 0.001 0.001"/>
      		</geometry>
          <material name="gray"/>
          <origin rpy="0 0 3.141592654" xyz="0.0 0.0 0.0"/>
  		</visual>
  
  		<collision>
          <geometry>
				    <mesh filename="./motoko_uprising.obj" scale="0.001 0.001 0.001"/>
      		</geometry>
        </collision>

        <contact>
          <lateral_friction value="0.0"/>
          <rolling_friction value="0.0"/>
          <stiffness value="300000"/>
          <damping value="1000"/>
        </contact>
  
   		<inertial>
            <mass value="0.063"/>
            <inertia ixx="0.0" ixy="0.0" ixz="0.0" iyy="0.0" iyz="0.0" izz="6e-4"/>
        </inertial>
	</link>




	<link name="left_wheel">
        <visual>
            <geometry>
                <cylinder length="0.012" radius="0.015"/>
            </geometry>
            <material name="black"/>
        </visual>
        <collision>
            <geometry>
                <cylinder length="0.012" radius="0.015"/>
            </geometry>
        </collision>
        <contact>
          <lateral_friction value="0.8"/>
          <rolling_friction value="0.0"/>
          <stiffness value="300000"/>
          <damping value="50"/>
        </contact>
        <inertial>
            <mass value="0.001"/>
            <inertia ixx="0.0" ixy="0.0" ixz="0.0" iyy="0.0" iyz="0.0" izz="1e-6"/>
        </inertial>
    </link>

    

	<link name="right_wheel">
        <visual>
            <geometry>
                <cylinder length="0.012" radius="0.015"/>
            </geometry>
            <material name="black"/>
        </visual>
        <collision>
            <geometry>
                <cylinder length="0.012" radius="0.015"/>
            </geometry>
        </collision>
        <contact>
          <lateral_friction value="0.8"/>
          <rolling_friction value="0.0"/>
          <stiffness value="300000"/>
          <damping value="50"/>
        </contact>
        <inertial>
            <mass value="0.001"/>
            <inertia ixx="0.0" ixy="0.0" ixz="0.0" iyy="0.0" iyz="0.0" izz="1e-6"/>
        </inertial>
    </link>







	 <joint name="chassis_left_wheel" type="continuous">
        <parent link="chassis"/>
        <child link="left_wheel"/>
        <origin rpy="-1.5708 0.0 0" xyz="-0.03 0.05 0.0025"/>
        <axis xyz="0 0 1"/>
     </joint>


    <joint name="chassis_right_wheel" type="continuous">
        <parent link="chassis"/>
        <child link="right_wheel"/>
        <origin rpy="1.5708 0.0 0" xyz="-0.03 -0.05 0.0025"/>
        <axis xyz="0 0 -1"/>
     </joint>



</robot>